Workbook
Name AverageWinRate: Score!$J$3
Name Vote: #REF!
Name FallBehind: Score!$X$9
Name TotalWins: Score!$F$3
Name LossRateTarget: Score!$X$7
Name Improve: #REF!
Name TotalGames: Score!$L$3
Name DoesNotMeetThreshold: #REF!
Name NumberOfDecks: Score!$B$3
Name PositiveNegative: #REF!
Name AvgPlayPerDeck: Score!$X$2
Name PlayDecKMore: #REF!
Name TotalLosses: Score!$H$3
Name PlayMore: #REF!
Name Threshold: Score!$X$8
Name AverageFunRate: #REF!
Name LossRate: Score!$X$7
Name WinRateTarget: Score!$X$6
Name ValidationNr: Score!$X$8
Name Nerf: #REF!
Name AveragePlayPerDeck: Score!$X$2

Sheet Wants List
B1: Legend | F1: Breya, Etherium Shaper | J1: Damia, Sage of Stone | N1: Derevi, Empyrial Tactician | R1: ="Cnt. "& sum(S2:S194) -> Cnt. 37 | T1: ="Card Names (Unique cards: " & COUNTA(T2:T302) &")" -> Card Names (Unique cards: 34) | V1: =TEXTJOIN(CHAR(10), TRUE,$B$19:$D$21, $F3:$F21, $J3:$J21, N3:$N21, $B24:$B44, $F24:$F44, $J24:$J44, $N24:$N44, $B47:$B67, $F47:$F67, $J47:$J67, $N47:$N67, $B70:$B90, $F70:$F90, $J70:$J90, $N70:$N90, $B93:$B113, $F93:$F113, $J93:$J113, $N93:$N113, $B116:$B131, $F116:$F131, $J116:$J131, $N116:$N131, $B134:$B159, $F134:$F159, $J134:$J159, $N134:$N159) -> Boltbender Horizon of Progress Change of Plans Witch-king of Angmar Voice of Victory Ainok strike leader Senu, Keen-Eyed Protector Practiced Scrollsmith \Aziza, Mage Tower Captain Personify ? Eldrazi Confluence ?Goobbue Gardener ?Frenzied Baloth \Intruder Alarm ?Neko-Te ?Flatline Agate Instigator token ?Agate Instigator ?Cosmogrand Zenith \Aziza, Mage Tower Captain Nanogene Conversion ?Keep Watch Welcoming vampire ?Brainstorm ?Share the Spoils ?Wyll's reversal ?Possessed Portal \Urza's cave \Arena of Glory \Wild Wasteland \Urza's cave \Damping Sphere \Sidisi, Regent of the Mire My Precious \Planar Incision Frost cliff siege ?Lyla, Holographic Assistant ?Thirst for Discovery ?Quick Study Secret Salvage Shadow-Rite Priest Agent venom ?Qarsi Revenant ?Surtr, Fiery Jotun Adrenaline Jockey ?Star athlete ?Ashling's Prerogative ?Orcish Lumberjack \Conduit of Worlds \Druid Class \Nissa, Resurgent Animist \Mina and Denn, Wildborn \Pair o' Dice Lost \Loamcrafter Faun \Horizon of Progress \Galadriel's Dismissal Shadow of the Second Sun Horizon of Progress ?Rites of Spring Winter, Misanthropic Guide \\Torpor orb Mox Jasper Frost cliff siege Horizon of Progress ?Echo of Eons \Tataru Taru Bilbo thief in the night Sage of the Beyond Fortune Teller's Talent ?Thieving Varmint \Trouble in Pairs \\Dawn's Truce Kodama of the West Tree Rune of Might \Bear Umbra \Kami of Whispered Hopes \Shield of the Oversoul Incubation Druid ?Canopy Cover /Alpha Authority /Esper Sentinel ?Angelic destiny ?Giant Inheritance \Restoration Seminar Underworld Breach Kroxa, Titan of Death's Hunger Junji, the Midnight Sky ?Balor ?Dawn's Truce Auriok Champion ?Ashes of the Abhorrent \?Leonin Elder \Pinnacle Monk \Seething Song \Molten-Core Maestro \Unexpected Windfall \?Spider manifestation
B2: When a cell contains the below symbols. It will be left out of the buy list on the right. | F2: In | H2: Out | J2: In | L2: Out | N2: In | P2: Out | S2: 1 | T2: {=UNIQUE($V$2:$V$300)} -> Boltbender | V2: =IFERROR(__xludf.DUMMYFUNCTION("IF(ISERROR(INDEX(IFERROR(FILTER(SPLIT($V$1, CHAR(10)), NOT(REGEXMATCH(SPLIT($V$1, CHAR(10)), ""\?|\\"")))), ROW()-ROW($T$1:$T$194))), """", INDEX(IFERROR(FILTER(SPLIT($V$1, CHAR(10)), NOT(REGEXMATCH(SPLIT($V$1, CHAR(10)), ""\?|\\"")))), ROW()-ROW($T$1:$T$"&"300)))"),"Boltbender ") -> Boltbender | W2: =COUNTIF($V$2:$V$300,$V2) -> 1
J3: Horizon of Progress | N3: Voice of Victory | S3: 3 | T3: Horizon of Progress | V3: =IFERROR(__xludf.DUMMYFUNCTION("IF(ISERROR(INDEX(IFERROR(FILTER(SPLIT($V$1, CHAR(10)), NOT(REGEXMATCH(SPLIT($V$1, CHAR(10)), ""\?|\\"")))), ROW()-ROW($T$1:$T$194))), """", INDEX(IFERROR(FILTER(SPLIT($V$1, CHAR(10)), NOT(REGEXMATCH(SPLIT($V$1, CHAR(10)), ""\?|\\"")))), ROW()-ROW($T$1:$T$"&"300)))"),"Horizon of Progress ") -> Horizon of Progress | W3: =COUNTIF($V$2:$V$300,$V3) -> 3
J4: Change of Plans | N4: Ainok strike leader | S4: 1 | T4: Change of Plans | V4: =IFERROR(__xludf.DUMMYFUNCTION("IF(ISERROR(INDEX(IFERROR(FILTER(SPLIT($V$1, CHAR(10)), NOT(REGEXMATCH(SPLIT($V$1, CHAR(10)), ""\?|\\"")))), ROW()-ROW($T$1:$T$194))), """", INDEX(IFERROR(FILTER(SPLIT($V$1, CHAR(10)), NOT(REGEXMATCH(SPLIT($V$1, CHAR(10)), ""\?|\\"")))), ROW()-ROW($T$1:$T$"&"300)))"),"Change of Plans") -> Change of Plans | W4: =COUNTIF($V$2:$V$300,$V4) -> 1
B5: ? = Questioning if it should go in | J5: Witch-king of Angmar | N5: Senu, Keen-Eyed Protector | S5: 2 | T5: Witch-king of Angmar | V5: =IFERROR(__xludf.DUMMYFUNCTION("IF(ISERROR(INDEX(IFERROR(FILTER(SPLIT($V$1, CHAR(10)), NOT(REGEXMATCH(SPLIT($V$1, CHAR(10)), ""\?|\\"")))), ROW()-ROW($T$1:$T$194))), """", INDEX(IFERROR(FILTER(SPLIT($V$1, CHAR(10)), NOT(REGEXMATCH(SPLIT($V$1, CHAR(10)), ""\?|\\"")))), ROW()-ROW($T$1:$T$"&"300)))"),"Witch-king of Angmar") -> Witch-king of Angmar | W5: =COUNTIF($V$2:$V$300,$V5) -> 1
B6: Code: Ctrl + Alt + Shift + 9 | S6: 1 | T6: Voice of Victory | V6: =IFERROR(__xludf.DUMMYFUNCTION("IF(ISERROR(INDEX(IFERROR(FILTER(SPLIT($V$1, CHAR(10)), NOT(REGEXMATCH(SPLIT($V$1, CHAR(10)), ""\?|\\"")))), ROW()-ROW($T$1:$T$194))), """", INDEX(IFERROR(FILTER(SPLIT($V$1, CHAR(10)), NOT(REGEXMATCH(SPLIT($V$1, CHAR(10)), ""\?|\\"")))), ROW()-ROW($T$1:$T$"&"300)))"),"Voice of Victory") -> Voice of Victory | W6: =COUNTIF($V$2:$V$300,$V6) -> 1
S7: 2 | T7: Ainok strike leader | V7: =IFERROR(__xludf.DUMMYFUNCTION("IF(ISERROR(INDEX(IFERROR(FILTER(SPLIT($V$1, CHAR(10)), NOT(REGEXMATCH(SPLIT($V$1, CHAR(10)), ""\?|\\"")))), ROW()-ROW($T$1:$T$194))), """", INDEX(IFERROR(FILTER(SPLIT($V$1, CHAR(10)), NOT(REGEXMATCH(SPLIT($V$1, CHAR(10)), ""\?|\\"")))), ROW()-ROW($T$1:$T$"&"300)))"),"Ainok strike leader") -> Ainok strike leader | W7: =COUNTIF($V$2:$V$300,$V7) -> 1
B8: \ = Own it already but it isn't in. | S8: 1 | T8: Senu, Keen-Eyed Protector | V8: =IFERROR(__xludf.DUMMYFUNCTION("IF(ISERROR(INDEX(IFERROR(FILTER(SPLIT($V$1, CHAR(10)), NOT(REGEXMATCH(SPLIT($V$1, CHAR(10)), ""\?|\\"")))), ROW()-ROW($T$1:$T$194))), """", INDEX(IFERROR(FILTER(SPLIT($V$1, CHAR(10)), NOT(REGEXMATCH(SPLIT($V$1, CHAR(10)), ""\?|\\"")))), ROW()-ROW($T$1:$T$"&"300)))"),"Senu, Keen-Eyed Protector") -> Senu, Keen-Eyed Protector | W8: =COUNTIF($V$2:$V$300,$V8) -> 1
B9: Code: Ctrl + Alt + Shift + 0 | S9: 1 | T9: Practiced Scrollsmith | V9: =IFERROR(__xludf.DUMMYFUNCTION("IF(ISERROR(INDEX(IFERROR(FILTER(SPLIT($V$1, CHAR(10)), NOT(REGEXMATCH(SPLIT($V$1, CHAR(10)), ""\?|\\"")))), ROW()-ROW($T$1:$T$194))), """", INDEX(IFERROR(FILTER(SPLIT($V$1, CHAR(10)), NOT(REGEXMATCH(SPLIT($V$1, CHAR(10)), ""\?|\\"")))), ROW()-ROW($T$1:$T$"&"300)))"),"Practiced Scrollsmith") -> Practiced Scrollsmith | W9: =COUNTIF($V$2:$V$300,$V9) -> 1
S10: 1 | T10: Personify | V10: =IFERROR(__xludf.DUMMYFUNCTION("IF(ISERROR(INDEX(IFERROR(FILTER(SPLIT($V$1, CHAR(10)), NOT(REGEXMATCH(SPLIT($V$1, CHAR(10)), ""\?|\\"")))), ROW()-ROW($T$1:$T$194))), """", INDEX(IFERROR(FILTER(SPLIT($V$1, CHAR(10)), NOT(REGEXMATCH(SPLIT($V$1, CHAR(10)), ""\?|\\"")))), ROW()-ROW($T$1:$T$"&"300)))"),"Personify") -> Personify | W10: =COUNTIF($V$2:$V$300,$V10) -> 1
B11: Remove "\ " or "? " from the selected cells | S11: 1 | T11: Agate Instigator token | V11: =IFERROR(__xludf.DUMMYFUNCTION("IF(ISERROR(INDEX(IFERROR(FILTER(SPLIT($V$1, CHAR(10)), NOT(REGEXMATCH(SPLIT($V$1, CHAR(10)), ""\?|\\"")))), ROW()-ROW($T$1:$T$194))), """", INDEX(IFERROR(FILTER(SPLIT($V$1, CHAR(10)), NOT(REGEXMATCH(SPLIT($V$1, CHAR(10)), ""\?|\\"")))), ROW()-ROW($T$1:$T$"&"300)))"),"Agate Instigator token") -> Agate Instigator token | W11: =COUNTIF($V$2:$V$300,$V11) -> 1
B12: Code: Ctrl + Alt + Shift + 8 | S12: 1 | T12: Nanogene Conversion | V12: =IFERROR(__xludf.DUMMYFUNCTION("IF(ISERROR(INDEX(IFERROR(FILTER(SPLIT($V$1, CHAR(10)), NOT(REGEXMATCH(SPLIT($V$1, CHAR(10)), ""\?|\\"")))), ROW()-ROW($T$1:$T$194))), """", INDEX(IFERROR(FILTER(SPLIT($V$1, CHAR(10)), NOT(REGEXMATCH(SPLIT($V$1, CHAR(10)), ""\?|\\"")))), ROW()-ROW($T$1:$T$"&"300)))"),"Nanogene Conversion") -> Nanogene Conversion | W12: =COUNTIF($V$2:$V$300,$V12) -> 1
S13: 1 | T13: Welcoming vampire | V13: =IFERROR(__xludf.DUMMYFUNCTION("IF(ISERROR(INDEX(IFERROR(FILTER(SPLIT($V$1, CHAR(10)), NOT(REGEXMATCH(SPLIT($V$1, CHAR(10)), ""\?|\\"")))), ROW()-ROW($T$1:$T$194))), """", INDEX(IFERROR(FILTER(SPLIT($V$1, CHAR(10)), NOT(REGEXMATCH(SPLIT($V$1, CHAR(10)), ""\?|\\"")))), ROW()-ROW($T$1:$T$"&"300)))"),"Welcoming vampire ") -> Welcoming vampire | W13: =COUNTIF($V$2:$V$300,$V13) -> 1
B14: Scryfall list | S14: 1 | T14: My Precious | V14: =IFERROR(__xludf.DUMMYFUNCTION("IF(ISERROR(INDEX(IFERROR(FILTER(SPLIT($V$1, CHAR(10)), NOT(REGEXMATCH(SPLIT($V$1, CHAR(10)), ""\?|\\"")))), ROW()-ROW($T$1:$T$194))), """", INDEX(IFERROR(FILTER(SPLIT($V$1, CHAR(10)), NOT(REGEXMATCH(SPLIT($V$1, CHAR(10)), ""\?|\\"")))), ROW()-ROW($T$1:$T$"&"300)))"),"My Precious") -> My Precious | W14: =COUNTIF($V$2:$V$300,$V14) -> 1
B15: Code: Ctrl + Alt + Shift + 7 | S15: 1 | T15: Frost cliff siege | V15: =IFERROR(__xludf.DUMMYFUNCTION("IF(ISERROR(INDEX(IFERROR(FILTER(SPLIT($V$1, CHAR(10)), NOT(REGEXMATCH(SPLIT($V$1, CHAR(10)), ""\?|\\"")))), ROW()-ROW($T$1:$T$194))), """", INDEX(IFERROR(FILTER(SPLIT($V$1, CHAR(10)), NOT(REGEXMATCH(SPLIT($V$1, CHAR(10)), ""\?|\\"")))), ROW()-ROW($T$1:$T$"&"300)))"),"Frost cliff siege") -> Frost cliff siege | W15: =COUNTIF($V$2:$V$300,$V15) -> 2
S16: 1 | T16: Secret Salvage | V16: =IFERROR(__xludf.DUMMYFUNCTION("IF(ISERROR(INDEX(IFERROR(FILTER(SPLIT($V$1, CHAR(10)), NOT(REGEXMATCH(SPLIT($V$1, CHAR(10)), ""\?|\\"")))), ROW()-ROW($T$1:$T$194))), """", INDEX(IFERROR(FILTER(SPLIT($V$1, CHAR(10)), NOT(REGEXMATCH(SPLIT($V$1, CHAR(10)), ""\?|\\"")))), ROW()-ROW($T$1:$T$"&"300)))"),"Secret Salvage ") -> Secret Salvage | W16: =COUNTIF($V$2:$V$300,$V16) -> 1
B17: Buy anyway | S17: 1 | T17: Shadow-Rite Priest | V17: =IFERROR(__xludf.DUMMYFUNCTION("IF(ISERROR(INDEX(IFERROR(FILTER(SPLIT($V$1, CHAR(10)), NOT(REGEXMATCH(SPLIT($V$1, CHAR(10)), ""\?|\\"")))), ROW()-ROW($T$1:$T$194))), """", INDEX(IFERROR(FILTER(SPLIT($V$1, CHAR(10)), NOT(REGEXMATCH(SPLIT($V$1, CHAR(10)), ""\?|\\"")))), ROW()-ROW($T$1:$T$"&"300)))"),"Shadow-Rite Priest") -> Shadow-Rite Priest | W17: =COUNTIF($V$2:$V$300,$V17) -> 1
B18: In | D18: In | S18: =IF($T18="","",IFERROR(VLOOKUP($T18,$V$2:$W$300,2,FALSE),"")) -> 1 | T18: Agent venom | V18: =IFERROR(__xludf.DUMMYFUNCTION("IF(ISERROR(INDEX(IFERROR(FILTER(SPLIT($V$1, CHAR(10)), NOT(REGEXMATCH(SPLIT($V$1, CHAR(10)), ""\?|\\"")))), ROW()-ROW($T$1:$T$194))), """", INDEX(IFERROR(FILTER(SPLIT($V$1, CHAR(10)), NOT(REGEXMATCH(SPLIT($V$1, CHAR(10)), ""\?|\\"")))), ROW()-ROW($T$1:$T$"&"300)))"),"Agent venom") -> Agent venom | W18: =COUNTIF($V$2:$V$300,$V18) -> 1
S19: =IF($T19="","",IFERROR(VLOOKUP($T19,$V$2:$W$300,2,FALSE),"")) -> 1 | T19: Adrenaline Jockey | V19: =IFERROR(__xludf.DUMMYFUNCTION("IF(ISERROR(INDEX(IFERROR(FILTER(SPLIT($V$1, CHAR(10)), NOT(REGEXMATCH(SPLIT($V$1, CHAR(10)), ""\?|\\"")))), ROW()-ROW($T$1:$T$194))), """", INDEX(IFERROR(FILTER(SPLIT($V$1, CHAR(10)), NOT(REGEXMATCH(SPLIT($V$1, CHAR(10)), ""\?|\\"")))), ROW()-ROW($T$1:$T$"&"300)))"),"Adrenaline Jockey") -> Adrenaline Jockey | W19: =COUNTIF($V$2:$V$300,$V19) -> 1
B20: Boltbender | S20: =IF($T20="","",IFERROR(VLOOKUP($T20,$V$2:$W$300,2,FALSE),"")) -> 1 | T20: Shadow of the Second Sun | V20: =IFERROR(__xludf.DUMMYFUNCTION("IF(ISERROR(INDEX(IFERROR(FILTER(SPLIT($V$1, CHAR(10)), NOT(REGEXMATCH(SPLIT($V$1, CHAR(10)), ""\?|\\"")))), ROW()-ROW($T$1:$T$194))), """", INDEX(IFERROR(FILTER(SPLIT($V$1, CHAR(10)), NOT(REGEXMATCH(SPLIT($V$1, CHAR(10)), ""\?|\\"")))), ROW()-ROW($T$1:$T$"&"300)))"),"Shadow of the Second Sun") -> Shadow of the Second Sun | W20: =COUNTIF($V$2:$V$300,$V20) -> 1
S21: =IF($T21="","",IFERROR(VLOOKUP($T21,$V$2:$W$300,2,FALSE),"")) -> 1 | T21: Winter, Misanthropic Guide | V21: =IFERROR(__xludf.DUMMYFUNCTION("IF(ISERROR(INDEX(IFERROR(FILTER(SPLIT($V$1, CHAR(10)), NOT(REGEXMATCH(SPLIT($V$1, CHAR(10)), ""\?|\\"")))), ROW()-ROW($T$1:$T$194))), """", INDEX(IFERROR(FILTER(SPLIT($V$1, CHAR(10)), NOT(REGEXMATCH(SPLIT($V$1, CHAR(10)), ""\?|\\"")))), ROW()-ROW($T$1:$T$"&"300)))"),"Horizon of Progress ") -> Horizon of Progress | W21: =COUNTIF($V$2:$V$300,$V21) -> 3
B22: Feather, the Redeemed | F22: Ghidorah, King of the Cosmos | J22: Ghyrson Starn, Kelermorph | N22: Jetmir, Nexus of Revels | S22: =IF($T22="","",IFERROR(VLOOKUP($T22,$V$2:$W$300,2,FALSE),"")) -> 1 | T22: Mox Jasper | V22: =IFERROR(__xludf.DUMMYFUNCTION("IF(ISERROR(INDEX(IFERROR(FILTER(SPLIT($V$1, CHAR(10)), NOT(REGEXMATCH(SPLIT($V$1, CHAR(10)), ""\?|\\"")))), ROW()-ROW($T$1:$T$194))), """", INDEX(IFERROR(FILTER(SPLIT($V$1, CHAR(10)), NOT(REGEXMATCH(SPLIT($V$1, CHAR(10)), ""\?|\\"")))), ROW()-ROW($T$1:$T$"&"300)))"),"Winter, Misanthropic Guide") -> Winter, Misanthropic Guide | W22: =COUNTIF($V$2:$V$300,$V22) -> 1
B23: In | D23: Out | F23: In | H23: Out | J23: In | L23: Out | N23: In | P23: Out | S23: =IF($T23="","",IFERROR(VLOOKUP($T23,$V$2:$W$300,2,FALSE),"")) -> 1 | T23: Bilbo thief in the night | V23: =IFERROR(__xludf.DUMMYFUNCTION("IF(ISERROR(INDEX(IFERROR(FILTER(SPLIT($V$1, CHAR(10)), NOT(REGEXMATCH(SPLIT($V$1, CHAR(10)), ""\?|\\"")))), ROW()-ROW($T$1:$T$194))), """", INDEX(IFERROR(FILTER(SPLIT($V$1, CHAR(10)), NOT(REGEXMATCH(SPLIT($V$1, CHAR(10)), ""\?|\\"")))), ROW()-ROW($T$1:$T$"&"300)))"),"Mox Jasper ") -> Mox Jasper | W23: =COUNTIF($V$2:$V$300,$V23) -> 1
B24: Practiced Scrollsmith | D24: Pinnacle monk | F24: ?Goobbue Gardener | J24: \Intruder Alarm | N24: Agate Instigator token | S24: =IF($T24="","",IFERROR(VLOOKUP($T24,$V$2:$W$300,2,FALSE),"")) -> 1 | T24: Sage of the Beyond | V24: =IFERROR(__xludf.DUMMYFUNCTION("IF(ISERROR(INDEX(IFERROR(FILTER(SPLIT($V$1, CHAR(10)), NOT(REGEXMATCH(SPLIT($V$1, CHAR(10)), ""\?|\\"")))), ROW()-ROW($T$1:$T$194))), """", INDEX(IFERROR(FILTER(SPLIT($V$1, CHAR(10)), NOT(REGEXMATCH(SPLIT($V$1, CHAR(10)), ""\?|\\"")))), ROW()-ROW($T$1:$T$"&"300)))"),"Frost cliff siege") -> Frost cliff siege | W24: =COUNTIF($V$2:$V$300,$V24) -> 2
B25: \Aziza, Mage Tower Captain | F25: ?Frenzied Baloth | S25: =IF($T25="","",IFERROR(VLOOKUP($T25,$V$2:$W$300,2,FALSE),"")) -> 1 | T25: Fortune Teller's Talent | V25: =IFERROR(__xludf.DUMMYFUNCTION("IF(ISERROR(INDEX(IFERROR(FILTER(SPLIT($V$1, CHAR(10)), NOT(REGEXMATCH(SPLIT($V$1, CHAR(10)), ""\?|\\"")))), ROW()-ROW($T$1:$T$194))), """", INDEX(IFERROR(FILTER(SPLIT($V$1, CHAR(10)), NOT(REGEXMATCH(SPLIT($V$1, CHAR(10)), ""\?|\\"")))), ROW()-ROW($T$1:$T$"&"300)))"),"Horizon of Progress ") -> Horizon of Progress | W25: =COUNTIF($V$2:$V$300,$V25) -> 3
B26: Personify | S26: =IF($T26="","",IFERROR(VLOOKUP($T26,$V$2:$W$300,2,FALSE),"")) -> 1 | T26: Kodama of the West Tree | V26: =IFERROR(__xludf.DUMMYFUNCTION("IF(ISERROR(INDEX(IFERROR(FILTER(SPLIT($V$1, CHAR(10)), NOT(REGEXMATCH(SPLIT($V$1, CHAR(10)), ""\?|\\"")))), ROW()-ROW($T$1:$T$194))), """", INDEX(IFERROR(FILTER(SPLIT($V$1, CHAR(10)), NOT(REGEXMATCH(SPLIT($V$1, CHAR(10)), ""\?|\\"")))), ROW()-ROW($T$1:$T$"&"300)))"),"Bilbo thief in the night") -> Bilbo thief in the night | W26: =COUNTIF($V$2:$V$300,$V26) -> 1
S27: =IF($T27="","",IFERROR(VLOOKUP($T27,$V$2:$W$300,2,FALSE),"")) -> 1 | T27: Rune of Might | V27: =IFERROR(__xludf.DUMMYFUNCTION("IF(ISERROR(INDEX(IFERROR(FILTER(SPLIT($V$1, CHAR(10)), NOT(REGEXMATCH(SPLIT($V$1, CHAR(10)), ""\?|\\"")))), ROW()-ROW($T$1:$T$194))), """", INDEX(IFERROR(FILTER(SPLIT($V$1, CHAR(10)), NOT(REGEXMATCH(SPLIT($V$1, CHAR(10)), ""\?|\\"")))), ROW()-ROW($T$1:$T$"&"300)))"),"Sage of the Beyond") -> Sage of the Beyond | W27: =COUNTIF($V$2:$V$300,$V27) -> 1
S28: =IF($T28="","",IFERROR(VLOOKUP($T28,$V$2:$W$300,2,FALSE),"")) -> 1 | T28: Incubation Druid | V28: =IFERROR(__xludf.DUMMYFUNCTION("IF(ISERROR(INDEX(IFERROR(FILTER(SPLIT($V$1, CHAR(10)), NOT(REGEXMATCH(SPLIT($V$1, CHAR(10)), ""\?|\\"")))), ROW()-ROW($T$1:$T$194))), """", INDEX(IFERROR(FILTER(SPLIT($V$1, CHAR(10)), NOT(REGEXMATCH(SPLIT($V$1, CHAR(10)), ""\?|\\"")))), ROW()-ROW($T$1:$T$"&"300)))"),"Fortune Teller's Talent ") -> Fortune Teller's Talent | W28: =COUNTIF($V$2:$V$300,$V28) -> 1
S29: =IF($T29="","",IFERROR(VLOOKUP($T29,$V$2:$W$300,2,FALSE),"")) -> 1 | T29: /Alpha Authority | V29: =IFERROR(__xludf.DUMMYFUNCTION("IF(ISERROR(INDEX(IFERROR(FILTER(SPLIT($V$1, CHAR(10)), NOT(REGEXMATCH(SPLIT($V$1, CHAR(10)), ""\?|\\"")))), ROW()-ROW($T$1:$T$194))), """", INDEX(IFERROR(FILTER(SPLIT($V$1, CHAR(10)), NOT(REGEXMATCH(SPLIT($V$1, CHAR(10)), ""\?|\\"")))), ROW()-ROW($T$1:$T$"&"300)))"),"Kodama of the West Tree") -> Kodama of the West Tree | W29: =COUNTIF($V$2:$V$300,$V29) -> 1
S30: =IF($T30="","",IFERROR(VLOOKUP($T30,$V$2:$W$300,2,FALSE),"")) -> 1 | T30: /Esper Sentinel | V30: =IFERROR(__xludf.DUMMYFUNCTION("IF(ISERROR(INDEX(IFERROR(FILTER(SPLIT($V$1, CHAR(10)), NOT(REGEXMATCH(SPLIT($V$1, CHAR(10)), ""\?|\\"")))), ROW()-ROW($T$1:$T$194))), """", INDEX(IFERROR(FILTER(SPLIT($V$1, CHAR(10)), NOT(REGEXMATCH(SPLIT($V$1, CHAR(10)), ""\?|\\"")))), ROW()-ROW($T$1:$T$"&"300)))"),"Rune of Might") -> Rune of Might | W30: =COUNTIF($V$2:$V$300,$V30) -> 1
S31: =IF($T31="","",IFERROR(VLOOKUP($T31,$V$2:$W$300,2,FALSE),"")) -> 1 | T31: Underworld Breach | V31: =IFERROR(__xludf.DUMMYFUNCTION("IF(ISERROR(INDEX(IFERROR(FILTER(SPLIT($V$1, CHAR(10)), NOT(REGEXMATCH(SPLIT($V$1, CHAR(10)), ""\?|\\"")))), ROW()-ROW($T$1:$T$194))), """", INDEX(IFERROR(FILTER(SPLIT($V$1, CHAR(10)), NOT(REGEXMATCH(SPLIT($V$1, CHAR(10)), ""\?|\\"")))), ROW()-ROW($T$1:$T$"&"300)))"),"Incubation Druid") -> Incubation Druid | W31: =COUNTIF($V$2:$V$300,$V31) -> 1
S32: =IF($T32="","",IFERROR(VLOOKUP($T32,$V$2:$W$300,2,FALSE),"")) -> 1 | T32: Kroxa, Titan of Death's Hunger | V32: =IFERROR(__xludf.DUMMYFUNCTION("IF(ISERROR(INDEX(IFERROR(FILTER(SPLIT($V$1, CHAR(10)), NOT(REGEXMATCH(SPLIT($V$1, CHAR(10)), ""\?|\\"")))), ROW()-ROW($T$1:$T$194))), """", INDEX(IFERROR(FILTER(SPLIT($V$1, CHAR(10)), NOT(REGEXMATCH(SPLIT($V$1, CHAR(10)), ""\?|\\"")))), ROW()-ROW($T$1:$T$"&"300)))"),"/Alpha Authority") -> /Alpha Authority | W32: =COUNTIF($V$2:$V$300,$V32) -> 1
S33: =IF($T33="","",IFERROR(VLOOKUP($T33,$V$2:$W$300,2,FALSE),"")) -> 1 | T33: Junji, the Midnight Sky | V33: =IFERROR(__xludf.DUMMYFUNCTION("IF(ISERROR(INDEX(IFERROR(FILTER(SPLIT($V$1, CHAR(10)), NOT(REGEXMATCH(SPLIT($V$1, CHAR(10)), ""\?|\\"")))), ROW()-ROW($T$1:$T$194))), """", INDEX(IFERROR(FILTER(SPLIT($V$1, CHAR(10)), NOT(REGEXMATCH(SPLIT($V$1, CHAR(10)), ""\?|\\"")))), ROW()-ROW($T$1:$T$"&"300)))"),"/Esper Sentinel") -> /Esper Sentinel | W33: =COUNTIF($V$2:$V$300,$V33) -> 1
S34: =IF($T34="","",IFERROR(VLOOKUP($T34,$V$2:$W$300,2,FALSE),"")) -> 1 | T34: Auriok Champion | V34: =IFERROR(__xludf.DUMMYFUNCTION("IF(ISERROR(INDEX(IFERROR(FILTER(SPLIT($V$1, CHAR(10)), NOT(REGEXMATCH(SPLIT($V$1, CHAR(10)), ""\?|\\"")))), ROW()-ROW($T$1:$T$194))), """", INDEX(IFERROR(FILTER(SPLIT($V$1, CHAR(10)), NOT(REGEXMATCH(SPLIT($V$1, CHAR(10)), ""\?|\\"")))), ROW()-ROW($T$1:$T$"&"300)))"),"Underworld Breach") -> Underworld Breach | W34: =COUNTIF($V$2:$V$300,$V34) -> 1
S35: =IF($T35="","",IFERROR(VLOOKUP($T35,$V$2:$W$300,2,FALSE),"")) | V35: =IFERROR(__xludf.DUMMYFUNCTION("IF(ISERROR(INDEX(IFERROR(FILTER(SPLIT($V$1, CHAR(10)), NOT(REGEXMATCH(SPLIT($V$1, CHAR(10)), ""\?|\\"")))), ROW()-ROW($T$1:$T$194))), """", INDEX(IFERROR(FILTER(SPLIT($V$1, CHAR(10)), NOT(REGEXMATCH(SPLIT($V$1, CHAR(10)), ""\?|\\"")))), ROW()-ROW($T$1:$T$"&"300)))"),"Kroxa, Titan of Death's Hunger") -> Kroxa, Titan of Death's Hunger | W35: =COUNTIF($V$2:$V$300,$V35) -> 1
S36: =IF($T36="","",IFERROR(VLOOKUP($T36,$V$2:$W$300,2,FALSE),"")) | V36: =IFERROR(__xludf.DUMMYFUNCTION("IF(ISERROR(INDEX(IFERROR(FILTER(SPLIT($V$1, CHAR(10)), NOT(REGEXMATCH(SPLIT($V$1, CHAR(10)), ""\?|\\"")))), ROW()-ROW($T$1:$T$194))), """", INDEX(IFERROR(FILTER(SPLIT($V$1, CHAR(10)), NOT(REGEXMATCH(SPLIT($V$1, CHAR(10)), ""\?|\\"")))), ROW()-ROW($T$1:$T$"&"300)))"),"Junji, the Midnight Sky") -> Junji, the Midnight Sky | W36: =COUNTIF($V$2:$V$300,$V36) -> 1
S37: =IF($T37="","",IFERROR(VLOOKUP($T37,$V$2:$W$300,2,FALSE),"")) | V37: =IFERROR(__xludf.DUMMYFUNCTION("IF(ISERROR(INDEX(IFERROR(FILTER(SPLIT($V$1, CHAR(10)), NOT(REGEXMATCH(SPLIT($V$1, CHAR(10)), ""\?|\\"")))), ROW()-ROW($T$1:$T$194))), """", INDEX(IFERROR(FILTER(SPLIT($V$1, CHAR(10)), NOT(REGEXMATCH(SPLIT($V$1, CHAR(10)), ""\?|\\"")))), ROW()-ROW($T$1:$T$"&"300)))"),"Auriok Champion") -> Auriok Champion | W37: =COUNTIF($V$2:$V$300,$V37) -> 1
S38: =IF($T38="","",IFERROR(VLOOKUP($T38,$V$2:$W$300,2,FALSE),"")) | V38: =IFERROR(__xludf.DUMMYFUNCTION("IF(ISERROR(INDEX(IFERROR(FILTER(SPLIT($V$1, CHAR(10)), NOT(REGEXMATCH(SPLIT($V$1, CHAR(10)), ""\?|\\"")))), ROW()-ROW($T$1:$T$194))), """", INDEX(IFERROR(FILTER(SPLIT($V$1, CHAR(10)), NOT(REGEXMATCH(SPLIT($V$1, CHAR(10)), ""\?|\\"")))), ROW()-ROW($T$1:$T$"&"300)))"),"") | W38: =COUNTIF($V$2:$V$300,$V38) -> 263
S39: =IF($T39="","",IFERROR(VLOOKUP($T39,$V$2:$W$300,2,FALSE),"")) | V39: =IFERROR(__xludf.DUMMYFUNCTION("IF(ISERROR(INDEX(IFERROR(FILTER(SPLIT($V$1, CHAR(10)), NOT(REGEXMATCH(SPLIT($V$1, CHAR(10)), ""\?|\\"")))), ROW()-ROW($T$1:$T$194))), """", INDEX(IFERROR(FILTER(SPLIT($V$1, CHAR(10)), NOT(REGEXMATCH(SPLIT($V$1, CHAR(10)), ""\?|\\"")))), ROW()-ROW($T$1:$T$"&"300)))"),"") | W39: =COUNTIF($V$2:$V$300,$V39) -> 263
S40: =IF($T40="","",IFERROR(VLOOKUP($T40,$V$2:$W$300,2,FALSE),"")) | V40: =IFERROR(__xludf.DUMMYFUNCTION("IF(ISERROR(INDEX(IFERROR(FILTER(SPLIT($V$1, CHAR(10)), NOT(REGEXMATCH(SPLIT($V$1, CHAR(10)), ""\?|\\"")))), ROW()-ROW($T$1:$T$194))), """", INDEX(IFERROR(FILTER(SPLIT($V$1, CHAR(10)), NOT(REGEXMATCH(SPLIT($V$1, CHAR(10)), ""\?|\\"")))), ROW()-ROW($T$1:$T$"&"300)))"),"") | W40: =COUNTIF($V$2:$V$300,$V40) -> 263
...

Sheet Score
D2: >> Sort Most Played << | F2: >> Sort Wins. << | N2: >> Sort Last << | S2: Most | W2: Average game per deck | X2: =TotalGames/NumberOfDecks -> 28.541667
B3: =COUNTA($D$6:$D$37) -> 24 | D3: Decks Totals: | F3: =SUM(F6:F36) -> 299 | H3: =SUM(H6:H37) -> 386 | J3: =if(L3=0,"",F3/L3) -> 0.43649635 | L3: =SUM(L6:L37) -> 685 | N3: Last Changed
B5: Nr | D5: Deck Name | F5: Win | H5: Loss | J5: W-Rate | L5: Total | N5: Date | P5: Last | S5: P-Evaluation | W5: Settings | AF5: Last
B6: =B7-1 -> 1 | D6: Obosh, the Preypiercer | F6: 20 | H6: 33 | J6: =if(L6=0,"",F6/L6) -> 0.37735849 | L6: =IF(F6="","",(F6+H6)) -> 53 | N6: 46156.647 | P6: Win | S6: =IF(OR($L6="",$L6=0),"",IF($L6<Threshold,"Threshold",IF($J6<(LossRate/100),"Just Right",IF($J6>($X$6/100),"Too Strong","Strong")))) -> Strong | W6: Max Win rate | X6: 45 | AF6: Most
B7: =B8-1 -> 2 | D7: Marchesa, the Black Rose | F7: 17 | H7: 31 | J7: =if(L7=0,"",F7/L7) -> 0.35416667 | L7: =IF(F7="","",(F7+H7)) -> 48 | N7: 46166.906 | P7: Win | S7: =IF(OR($L7="",$L7=0),"",IF($L7<Threshold,"Threshold",IF($J7<(LossRate/100),"Just Right",IF($J7>($X$6/100),"Too Strong","Strong")))) -> Just Right | W7: Strong Win Rate | X7: 36 | AF7: Wins
B8: =B9-1 -> 3 | D8: Breya, Etherium Shaper | F8: 16 | H8: 26 | J8: =if(L8=0,"",F8/L8) -> 0.38095238 | L8: =IF(F8="","",(F8+H8)) -> 42 | N8: 46156.463 | P8: Loss | S8: =IF(OR($L8="",$L8=0),"",IF($L8<Threshold,"Threshold",IF($J8<(LossRate/100),"Just Right",IF($J8>($X$6/100),"Too Strong","Strong")))) -> Strong | W8: Treshold | X8: 8 | Z8: Select a deck for the graph | AA8: Entries
B9: =B10-1 -> 4 | D9: Tariel, Reckoner of Souls | F9: 15 | H9: 25 | J9: =if(L9=0,"",F9/L9) -> 0.375 | L9: =IF(F9="","",(F9+H9)) -> 40 | N9: 46156.56 | P9: Loss | S9: =IF(OR($L9="",$L9=0),"",IF($L9<Threshold,"Threshold",IF($J9<(LossRate/100),"Just Right",IF($J9>($X$6/100),"Too Strong","Strong")))) -> Strong | W9: Fall behind | X9: 1.5 | Z9: All | AA9: =max(History!K2:K971)+max(History!L2:L971) -> 704
B10: =B11-1 -> 5 | D10: Saskia the Unyielding | F10: 13 | H10: 27 | J10: =if(L10=0,"",F10/L10) -> 0.325 | L10: =IF(F10="","",(F10+H10)) -> 40 | N10: 46118.787 | P10: Loss | S10: =IF(OR($L10="",$L10=0),"",IF($L10<Threshold,"Threshold",IF($J10<(LossRate/100),"Just Right",IF($J10>($X$6/100),"Too Strong","Strong")))) -> Just Right
B11: =B12-1 -> 6 | D11: Ikra // Tymna | F11: 15 | H11: 22 | J11: =IF(L11="","",F11/L11) -> 0.40540541 | L11: =IF(F11="","",(F11+H11)) -> 37 | N11: 46156.61 | P11: Loss | S11: =IF(OR($L11="",$L11=0),"",IF($L11<Threshold,"Threshold",IF($J11<(LossRate/100),"Just Right",IF($J11>($X$6/100),"Too Strong","Strong")))) -> Strong
B12: =B13-1 -> 7 | D12: Derevi, Empyrial Tactician | F12: 13 | H12: 22 | J12: =if(L12=0,"",F12/L12) -> 0.37142857 | L12: =IF(F12="","",(F12+H12)) -> 35 | N12: 46061.637 | P12: Loss | S12: =IF(OR($L12="",$L12=0),"",IF($L12<Threshold,"Threshold",IF($J12<(LossRate/100),"Just Right",IF($J12>($X$6/100),"Too Strong","Strong")))) -> Strong
B13: =B14-1 -> 8 | D13: Kykar, Wind's Fury | F13: 17 | H13: 15 | J13: =if(L13=0,"",F13/L13) -> 0.53125 | L13: =IF(F13="","",(F13+H13)) -> 32 | N13: 46061.731 | P13: Loss | S13: =IF(OR($L13="",$L13=0),"",IF($L13<Threshold,"Threshold",IF($J13<(LossRate/100),"Just Right",IF($J13>($X$6/100),"Too Strong","Strong")))) -> Too Strong
B14: =B15-1 -> 9 | D14: Feather, the Redeemed | F14: 15 | H14: 17 | J14: =if(L14=0,"",F14/L14) -> 0.46875 | L14: =IF(F14="","",(F14+H14)) -> 32 | N14: 46061.682 | P14: Loss | S14: =IF(OR($L14="",$L14=0),"",IF($L14<Threshold,"Threshold",IF($J14<(LossRate/100),"Just Right",IF($J14>($X$6/100),"Too Strong","Strong")))) -> Too Strong
B15: =B16-1 -> 10 | D15: Taigam, Ojutai Master | F15: 10 | H15: 20 | J15: =if(L15=0,"",F15/L15) -> 0.33333333 | L15: =IF(F15="","",(F15+H15)) -> 30 | N15: 46156.808 | P15: Win | S15: =IF(OR($L15="",$L15=0),"",IF($L15<Threshold,"Threshold",IF($J15<(LossRate/100),"Just Right",IF($J15>($X$6/100),"Too Strong","Strong")))) -> Just Right
B16: =B17-1 -> 11 | D16: Illuna / Ghidorah | F16: 7 | H16: 20 | J16: =if(L16=0,"",F16/L16) -> 0.25925926 | L16: =IF(F16="","",(F16+H16)) -> 27 | N16: 46033.531 | P16: Loss | S16: =IF(OR($L16="",$L16=0),"",IF($L16<Threshold,"Threshold",IF($J16<(LossRate/100),"Just Right",IF($J16>($X$6/100),"Too Strong","Strong")))) -> Just Right
B17: =B18-1 -> 12 | D17: Minn, Wily Illusionist | F17: 16 | H17: 11 | J17: =if(L17=0,"",F17/L17) -> 0.59259259 | L17: =IF(F17="","",(F17+H17)) -> 27 | N17: 46004.874 | P17: Win | S17: =IF(OR($L17="",$L17=0),"",IF($L17<Threshold,"Threshold",IF($J17<(LossRate/100),"Just Right",IF($J17>($X$6/100),"Too Strong","Strong")))) -> Too Strong
B18: =B19-1 -> 13 | D18: Scion, The Ur Dragon | F18: 12 | H18: 15 | J18: =if(L18=0,"",F18/L18) -> 0.44444444 | L18: =IF(F18="","",(F18+H18)) -> 27 | N18: 45920.56 | P18: Win | S18: =IF(OR($L18="",$L18=0),"",IF($L18<Threshold,"Threshold",IF($J18<(LossRate/100),"Just Right",IF($J18>($X$6/100),"Too Strong","Strong")))) -> Strong
B19: =B20-1 -> 14 | D19: Wort, The raid Mother | F19: 12 | H19: 14 | J19: =if(L19=0,"",F19/L19) -> 0.46153846 | L19: =IF(F19="","",(F19+H19)) -> 26 | N19: 46156.498 | P19: Win | S19: =IF(OR($L19="",$L19=0),"",IF($L19<Threshold,"Threshold",IF($J19<(LossRate/100),"Just Right",IF($J19>($X$6/100),"Too Strong","Strong")))) -> Too Strong
B20: =B21-1 -> 15 | D20: Teysa, Orzhov Scion | F20: 18 | H20: 6 | J20: =if(L20=0,"",F20/L20) -> 0.75 | L20: =IF(F20="","",(F20+H20)) -> 24 | N20: 46061.637 | P20: Win | S20: =IF(OR($L20="",$L20=0),"",IF($L20<Threshold,"Threshold",IF($J20<(LossRate/100),"Just Right",IF($J20>($X$6/100),"Too Strong","Strong")))) -> Too Strong
B21: =B22-1 -> 16 | D21: Sram, Senior Edificer | F21: 15 | H21: 9 | J21: =if(L21=0,"",F21/L21) -> 0.625 | L21: =IF(F21="","",(F21+H21)) -> 24 | N21: 45934.826 | P21: Win | S21: =IF(OR($L21="",$L21=0),"",IF($L21<Threshold,"Threshold",IF($J21<(LossRate/100),"Just Right",IF($J21>($X$6/100),"Too Strong","Strong")))) -> Too Strong
B22: =B23-1 -> 17 | D22: Oona, Queen of Fae | F22: 13 | H22: 11 | J22: =if(L22=0,"",F22/L22) -> 0.54166667 | L22: =IF(F22="","",(F22+H22)) -> 24 | N22: 46156.808 | P22: Win | S22: =IF(OR($L22="",$L22=0),"",IF($L22<Threshold,"Threshold",IF($J22<(LossRate/100),"Just Right",IF($J22>($X$6/100),"Too Strong","Strong")))) -> Too Strong
B23: =B24-1 -> 18 | D23: Damia, Sage of Stone | F23: 8 | H23: 15 | J23: =if(L23=0,"",F23/L23) -> 0.34782609 | L23: =IF(F23="","",(F23+H23)) -> 23 | N23: 46116.778 | P23: Loss | S23: =IF(OR($L23="",$L23=0),"",IF($L23<Threshold,"Threshold",IF($J23<(LossRate/100),"Just Right",IF($J23>($X$6/100),"Too Strong","Strong")))) -> Just Right
... B28: =B29-1 -> 23 | D28: Jetmir, Nexus of Revels | F28: 9 | H28: 7 | J28: =if(L28=0,"",F28/L28) -> 0.5625 | L28: =IF(F28="","",(F28+H28)) -> 16 | N28: 45934.555 | P28: Win | S28: =IF(OR($L28="",$L28=0),"",IF($L28<Threshold,"Threshold",IF($J28<(LossRate/100),"Just Right",IF($J28>($X$6/100),"Too Strong","Strong")))) -> Too Strong
B29: =B30-1 -> 24 | D29: Calix, Guided by Fate | F29: 1 | G29: 0 | H29: 0 | J29: =if(L29=0,"",F29/L29) -> 1 | L29: =IF(F29="","",(F29+H29)) -> 1 | N29: 46166.787 | P29: Win | S29: =IF(OR($L29="",$L29=0),"",IF($L29<Threshold,"Threshold",IF($J29<(LossRate/100),"Just Right",IF($J29>($X$6/100),"Too Strong","Strong")))) -> Threshold
B30: =B31-1 -> 25 | S30: =IF(OR($L30="",$L30=0),"",IF($L30<Threshold,"Threshold",IF($J30<(LossRate/100),"Just Right",IF($J30>($X$6/100),"Too Strong","Strong"))))
B31: =B32-1 -> 26 | S31: =IF(OR($L31="",$L31=0),"",IF($L31<Threshold,"Threshold",IF($J31<(LossRate/100),"Just Right",IF($J31>($X$6/100),"Too Strong","Strong"))))
B32: =B33-1 -> 27 | S32: =IF(OR($L32="",$L32=0),"",IF($L32<Threshold,"Threshold",IF($J32<(LossRate/100),"Just Right",IF($J32>($X$6/100),"Too Strong","Strong"))))
B33: =B34-1 -> 28 | S33: =IF(OR($L33="",$L33=0),"",IF($L33<Threshold,"Threshold",IF($J33<(LossRate/100),"Just Right",IF($J33>($X$6/100),"Too Strong","Strong")))) | AB33: =Score!D33
B34: =B35-1 -> 29 | S34: =IF(OR($L34="",$L34=0),"",IF($L34<Threshold,"Threshold",IF($J34<(LossRate/100),"Just Right",IF($J34>($X$6/100),"Too Strong","Strong")))) | AB34: =Score!D34
B35: =B36-1 -> 30 | S35: =IF(OR($L35="",$L35=0),"",IF($L35<Threshold,"Threshold",IF($J35<(LossRate/100),"Just Right",IF($J35>($X$6/100),"Too Strong","Strong")))) | AB35: =Score!D35
B36: =B37-1 -> 31 | S36: =IF(OR($L36="",$L36=0),"",IF($L36<Threshold,"Threshold",IF($J36<(LossRate/100),"Just Right",IF($J36>($X$6/100),"Too Strong","Strong")))) | AB36: =Score!D36
B37: =B38-1 -> 32 | S37: =IF(OR($L37="",$L37=0),"",IF($L37<Threshold,"Threshold",IF($J37<(LossRate/100),"Just Right",IF($J37>($X$6/100),"Too Strong","Strong")))) | AB37: =Score!D37
B38: 33 | D38: All | AB38: All
D41: Retired decks
D42: Gahiji | F42: 7 | H42: 11 | J42: =IF(($F42+$H42)=0,"",($F42/($F42+$H42))) -> 0.38888889 | L42: =IF($F42+$H42>0,$F42+$H42,"") -> 18 | S42: =IF(OR($L42="",$L42=0),"",IF($L42<Threshold,"Threshold",IF($J42<(LossRate/100),"Just Right",IF($J42>($X$6/100),"Too Strong","Strong")))) -> Strong
D43: Traximundar | F43: ?? | H43: ?? | J43: ?? | L43: ?? | S43: ??
D44: Sythis, Harvest's Hand | F44: 15 | H44: 7 | J44: =if(L44=0,"",F44/L44) -> 0.68181818 | L44: =IF(F44="","",(F44+H44)) -> 22 | N44: 46116.537 | P44: Loss | S44: =IF(OR($L44="",$L44=0),"",IF($L44<Threshold,"Threshold",IF($J44<(LossRate/100),"Just Right",IF($J44>($X$6/100),"Too Strong","Strong")))) -> Too Strong

Sheet Set Fetcher
A1: Instructions: | G1: Look up legend. https://en.wikipedia.org/wiki/List_of_Magic:_The_Gathering_sets | M1: You can copy paste the set information from scryfall or from chatgpt4 and the text will convert properly
A2: Copy the final want list into ManaMaza. Paste the list in Collumn A. Get a set name for each so you can sort it on sets, it culls acces data as well.
A3: Input | B3: Count | C3: Card Name | D3: Set Name | E3: Set Code | G3: Input any missing set by copying it from Scryfall. For example: Commander Collection: Green (CC1)
A4: 1 Brotherhood Regalia (ACR) 71 | B4: =if(A4="","", LEFT(A4, FIND(" ", A4)-1)) -> 1 | C4: =if(A4="","",TRIM(MID(A4, FIND(" ", A4)+1, FIND("(", A4)-FIND(" ", A4)-2))) -> Brotherhood Regalia | D4: =if(A4="","",VLOOKUP(E4, $J:$K, 2, FALSE)) -> Adventures in the Forgotten Realms | E4: =if(A4="","",SUBSTITUTE(SUBSTITUTE(MID(A4, FIND("(", A4), FIND(")", A4) - FIND("(", A4) + 1), "(" , ""), ")" , "")) -> ACR | G4: 9ED = Ninth Edition | J4: =if(M4="","", LEFT(M4, FIND(" = ", M4)-1)) -> 9ED | K4: =if(M4="","", TRIM(MID(M4, FIND("= ", M4) + 2, LEN(M4)))) -> Ninth Edition | M4: =if(G4="","",IF(ISNUMBER(SEARCH("=", G4)), G4, TRIM(MID(G4, FIND("(" , G4) + 1, FIND(")", G4) - FIND("(" , G4) - 1)) & " = " & TRIM(LEFT(G4, FIND("(" , G4) - 1)))) -> 9ED = Ninth Edition
A5: 3 Desynchronization (ACR) 16 | B5: =if(A5="","", LEFT(A5, FIND(" ", A5)-1)) -> 3 | C5: =if(A5="","",TRIM(MID(A5, FIND(" ", A5)+1, FIND("(", A5)-FIND(" ", A5)-2))) -> Desynchronization | D5: =if(A5="","",VLOOKUP(E5, $J:$K, 2, FALSE)) -> Adventures in the Forgotten Realms | E5: =if(A5="","",SUBSTITUTE(SUBSTITUTE(MID(A5, FIND("(", A5), FIND(")", A5) - FIND("(", A5) + 1), "(" , ""), ")" , "")) -> ACR | G5: ACR = Adventures in the Forgotten Realms | J5: =if(M5="","", LEFT(M5, FIND(" = ", M5)-1)) -> ACR | K5: =if(M5="","", TRIM(MID(M5, FIND("= ", M5) + 2, LEN(M5)))) -> Adventures in the Forgotten Realms | M5: =if(G5="","",IF(ISNUMBER(SEARCH("=", G5)), G5, TRIM(MID(G5, FIND("(" , G5) + 1, FIND(")", G5) - FIND("(" , G5) - 1)) & " = " & TRIM(LEFT(G5, FIND("(" , G5) - 1)))) -> ACR = Adventures in the Forgotten Realms
A6: 1 Eagle Vision (ACR) 17 | B6: =if(A6="","", LEFT(A6, FIND(" ", A6)-1)) -> 1 | C6: =if(A6="","",TRIM(MID(A6, FIND(" ", A6)+1, FIND("(", A6)-FIND(" ", A6)-2))) -> Eagle Vision | D6: =if(A6="","",VLOOKUP(E6, $J:$K, 2, FALSE)) -> Adventures in the Forgotten Realms | E6: =if(A6="","",SUBSTITUTE(SUBSTITUTE(MID(A6, FIND("(", A6), FIND(")", A6) - FIND("(", A6) + 1), "(" , ""), ")" , "")) -> ACR | G6: AER = Aether Revolt | J6: =if(M6="","", LEFT(M6, FIND(" = ", M6)-1)) -> AER | K6: =if(M6="","", TRIM(MID(M6, FIND("= ", M6) + 2, LEN(M6)))) -> Aether Revolt | M6: =if(G6="","",IF(ISNUMBER(SEARCH("=", G6)), G6, TRIM(MID(G6, FIND("(" , G6) + 1, FIND(")", G6) - FIND("(" , G6) - 1)) & " = " & TRIM(LEFT(G6, FIND("(" , G6) - 1)))) -> AER = Aether Revolt
A7: 1 Haystack (ACR) 5 | B7: =if(A7="","", LEFT(A7, FIND(" ", A7)-1)) -> 1 | C7: =if(A7="","",TRIM(MID(A7, FIND(" ", A7)+1, FIND("(", A7)-FIND(" ", A7)-2))) -> Haystack | D7: =if(A7="","",VLOOKUP(E7, $J:$K, 2, FALSE)) -> Adventures in the Forgotten Realms | E7: =if(A7="","",SUBSTITUTE(SUBSTITUTE(MID(A7, FIND("(", A7), FIND(")", A7) - FIND("(", A7) + 1), "(" , ""), ")" , "")) -> ACR | G7: AKH = Amonkhet | J7: =if(M7="","", LEFT(M7, FIND(" = ", M7)-1)) -> AKH | K7: =if(M7="","", TRIM(MID(M7, FIND("= ", M7) + 2, LEN(M7)))) -> Amonkhet | M7: =if(G7="","",IF(ISNUMBER(SEARCH("=", G7)), G7, TRIM(MID(G7, FIND("(" , G7) + 1, FIND(")", G7) - FIND("(" , G7) - 1)) & " = " & TRIM(LEFT(G7, FIND("(" , G7) - 1)))) -> AKH = Amonkhet
A8: 1 Felidar Guardian (AER) 19 | B8: =if(A8="","", LEFT(A8, FIND(" ", A8)-1)) -> 1 | C8: =if(A8="","",TRIM(MID(A8, FIND(" ", A8)+1, FIND("(", A8)-FIND(" ", A8)-2))) -> Felidar Guardian | D8: =if(A8="","",VLOOKUP(E8, $J:$K, 2, FALSE)) -> Aether Revolt | E8: =if(A8="","",SUBSTITUTE(SUBSTITUTE(MID(A8, FIND("(", A8), FIND(")", A8) - FIND("(", A8) + 1), "(" , ""), ")" , "")) -> AER | G8: ATH = Anthologies | J8: =if(M8="","", LEFT(M8, FIND(" = ", M8)-1)) -> ATH | K8: =if(M8="","", TRIM(MID(M8, FIND("= ", M8) + 2, LEN(M8)))) -> Anthologies | M8: =if(G8="","",IF(ISNUMBER(SEARCH("=", G8)), G8, TRIM(MID(G8, FIND("(" , G8) + 1, FIND(")", G8) - FIND("(" , G8) - 1)) & " = " & TRIM(LEFT(G8, FIND("(" , G8) - 1)))) -> ATH = Anthologies
A9: 3 Strip Mine (ATH) 77 | B9: =if(A9="","", LEFT(A9, FIND(" ", A9)-1)) -> 3 | C9: =if(A9="","",TRIM(MID(A9, FIND(" ", A9)+1, FIND("(", A9)-FIND(" ", A9)-2))) -> Strip Mine | D9: =if(A9="","",VLOOKUP(E9, $J:$K, 2, FALSE)) -> Anthologies | E9: =if(A9="","",SUBSTITUTE(SUBSTITUTE(MID(A9, FIND("(", A9), FIND(")", A9) - FIND("(", A9) + 1), "(" , ""), ")" , "")) -> ATH | G9: BFZ = Battle for Zendikar | J9: =if(M9="","", LEFT(M9, FIND(" = ", M9)-1)) -> BFZ | K9: =if(M9="","", TRIM(MID(M9, FIND("= ", M9) + 2, LEN(M9)))) -> Battle for Zendikar | M9: =if(G9="","",IF(ISNUMBER(SEARCH("=", G9)), G9, TRIM(MID(G9, FIND("(" , G9) + 1, FIND(")", G9) - FIND("(" , G9) - 1)) & " = " & TRIM(LEFT(G9, FIND("(" , G9) - 1)))) -> BFZ = Battle for Zendikar
A10: 2 Agate Instigator (BLC) 21 | B10: =if(A10="","", LEFT(A10, FIND(" ", A10)-1)) -> 2 | C10: =if(A10="","",TRIM(MID(A10, FIND(" ", A10)+1, FIND("(", A10)-FIND(" ", A10)-2))) -> Agate Instigator | D10: =if(A10="","",VLOOKUP(E10, $J:$K, 2, FALSE)) -> Battle for Zendikar | E10: =if(A10="","",SUBSTITUTE(SUBSTITUTE(MID(A10, FIND("(", A10), FIND(")", A10) - FIND("(", A10) + 1), "(" , ""), ")" , "")) -> BLC | G10: BIG = The Big Score | J10: =if(M10="","", LEFT(M10, FIND(" = ", M10)-1)) -> BIG | K10: =if(M10="","", TRIM(MID(M10, FIND("= ", M10) + 2, LEN(M10)))) -> The Big Score | M10: =if(G10="","",IF(ISNUMBER(SEARCH("=", G10)), G10, TRIM(MID(G10, FIND("(" , G10) + 1, FIND(")", G10) - FIND("(" , G10) - 1)) & " = " & TRIM(LEFT(G10, FIND("(" , G10) - 1)))) -> BIG = The Big Score
A11: 1 Jacked Rabbit (BLC) 9 | B11: =if(A11="","", LEFT(A11, FIND(" ", A11)-1)) -> 1 | C11: =if(A11="","",TRIM(MID(A11, FIND(" ", A11)+1, FIND("(", A11)-FIND(" ", A11)-2))) -> Jacked Rabbit | D11: =if(A11="","",VLOOKUP(E11, $J:$K, 2, FALSE)) -> Battle for Zendikar | E11: =if(A11="","",SUBSTITUTE(SUBSTITUTE(MID(A11, FIND("(", A11), FIND(")", A11) - FIND("(", A11) + 1), "(" , ""), ")" , "")) -> BLC | G11: BLB = Battlebond | J11: =if(M11="","", LEFT(M11, FIND(" = ", M11)-1)) -> BLB | K11: =if(M11="","", TRIM(MID(M11, FIND("= ", M11) + 2, LEN(M11)))) -> Battlebond | M11: =if(G11="","",IF(ISNUMBER(SEARCH("=", G11)), G11, TRIM(MID(G11, FIND("(" , G11) + 1, FIND(")", G11) - FIND("(" , G11) - 1)) & " = " & TRIM(LEFT(G11, FIND("(" , G11) - 1)))) -> BLB = Battlebond
A12: 1 Pollywog Prodigy (BLC) 15 | B12: =if(A12="","", LEFT(A12, FIND(" ", A12)-1)) -> 1 | C12: =if(A12="","",TRIM(MID(A12, FIND(" ", A12)+1, FIND("(", A12)-FIND(" ", A12)-2))) -> Pollywog Prodigy | D12: =if(A12="","",VLOOKUP(E12, $J:$K, 2, FALSE)) -> Battle for Zendikar | E12: =if(A12="","",SUBSTITUTE(SUBSTITUTE(MID(A12, FIND("(", A12), FIND(")", A12) - FIND("(", A12) + 1), "(" , ""), ")" , "")) -> BLC | G12: BLC = Battle for Zendikar | J12: =if(M12="","", LEFT(M12, FIND(" = ", M12)-1)) -> BLC | K12: =if(M12="","", TRIM(MID(M12, FIND("= ", M12) + 2, LEN(M12)))) -> Battle for Zendikar | M12: =if(G12="","",IF(ISNUMBER(SEARCH("=", G12)), G12, TRIM(MID(G12, FIND("(" , G12) + 1, FIND(")", G12) - FIND("(" , G12) - 1)) & " = " & TRIM(LEFT(G12, FIND("(" , G12) - 1)))) -> BLC = Battle for Zendikar
A13: 1 Skyclave Apparition (BLC) 154 | B13: =if(A13="","", LEFT(A13, FIND(" ", A13)-1)) -> 1 | C13: =if(A13="","",TRIM(MID(A13, FIND(" ", A13)+1, FIND("(", A13)-FIND(" ", A13)-2))) -> Skyclave Apparition | D13: =if(A13="","",VLOOKUP(E13, $J:$K, 2, FALSE)) -> Battle for Zendikar | E13: =if(A13="","",SUBSTITUTE(SUBSTITUTE(MID(A13, FIND("(", A13), FIND(")", A13) - FIND("(", A13) + 1), "(" , ""), ")" , "")) -> BLC | G13: C19 = Commander 2019 | J13: =if(M13="","", LEFT(M13, FIND(" = ", M13)-1)) -> C19 | K13: =if(M13="","", TRIM(MID(M13, FIND("= ", M13) + 2, LEN(M13)))) -> Commander 2019 | M13: =if(G13="","",IF(ISNUMBER(SEARCH("=", G13)), G13, TRIM(MID(G13, FIND("(" , G13) + 1, FIND(")", G13) - FIND("(" , G13) - 1)) & " = " & TRIM(LEFT(G13, FIND("(" , G13) - 1)))) -> C19 = Commander 2019
A14: 1 Beza, the Bounding Spring (BLB) 2 | B14: =if(A14="","", LEFT(A14, FIND(" ", A14)-1)) -> 1 | C14: =if(A14="","",TRIM(MID(A14, FIND(" ", A14)+1, FIND("(", A14)-FIND(" ", A14)-2))) -> Beza, the Bounding Spring | D14: =if(A14="","",VLOOKUP(E14, $J:$K, 2, FALSE)) -> Battlebond | E14: =if(A14="","",SUBSTITUTE(SUBSTITUTE(MID(A14, FIND("(", A14), FIND(")", A14) - FIND("(", A14) + 1), "(" , ""), ")" , "")) -> BLB | G14: C20 = Commander 2020 | J14: =if(M14="","", LEFT(M14, FIND(" = ", M14)-1)) -> C20 | K14: =if(M14="","", TRIM(MID(M14, FIND("= ", M14) + 2, LEN(M14)))) -> Commander 2020 | M14: =if(G14="","",IF(ISNUMBER(SEARCH("=", G14)), G14, TRIM(MID(G14, FIND("(" , G14) + 1, FIND(")", G14) - FIND("(" , G14) - 1)) & " = " & TRIM(LEFT(G14, FIND("(" , G14) - 1)))) -> C20 = Commander 2020
A15: 1 Coruscation Mage (BLB) 131 | B15: =if(A15="","", LEFT(A15, FIND(" ", A15)-1)) -> 1 | C15: =if(A15="","",TRIM(MID(A15, FIND(" ", A15)+1, FIND("(", A15)-FIND(" ", A15)-2))) -> Coruscation Mage | D15: =if(A15="","",VLOOKUP(E15, $J:$K, 2, FALSE)) -> Battlebond | E15: =if(A15="","",SUBSTITUTE(SUBSTITUTE(MID(A15, FIND("(", A15), FIND(")", A15) - FIND("(", A15) + 1), "(" , ""), ")" , "")) -> BLB | G15: C21 = Commander 2021 | J15: =if(M15="","", LEFT(M15, FIND(" = ", M15)-1)) -> C21 | K15: =if(M15="","", TRIM(MID(M15, FIND("= ", M15) + 2, LEN(M15)))) -> Commander 2021 | M15: =if(G15="","",IF(ISNUMBER(SEARCH("=", G15)), G15, TRIM(MID(G15, FIND("(" , G15) + 1, FIND(")", G15) - FIND("(" , G15) - 1)) & " = " & TRIM(LEFT(G15, FIND("(" , G15) - 1)))) -> C21 = Commander 2021
... A17: 1 Fountainport (BLB) 253 | B17: =if(A17="","", LEFT(A17, FIND(" ", A17)-1)) -> 1 | C17: =if(A17="","",TRIM(MID(A17, FIND(" ", A17)+1, FIND("(", A17)-FIND(" ", A17)-2))) -> Fountainport | D17: =if(A17="","",VLOOKUP(E17, $J:$K, 2, FALSE)) -> Battlebond | E17: =if(A17="","",SUBSTITUTE(SUBSTITUTE(MID(A17, FIND("(", A17), FIND(")", A17) - FIND("(", A17) + 1), "(" , ""), ")" , "")) -> BLB | G17: CLU = Commander Legends: Battle for Baldur's Gate | J17: =if(M17="","", LEFT(M17, FIND(" = ", M17)-1)) -> CLU | K17: =if(M17="","", TRIM(MID(M17, FIND("= ", M17) + 2, LEN(M17)))) -> Commander Legends: Battle for Baldur's Gate | M17: =if(G17="","",IF(ISNUMBER(SEARCH("=", G17)), G17, TRIM(MID(G17, FIND("(" , G17) + 1, FIND(")", G17) - FIND("(" , G17) - 1)) & " = " & TRIM(LEFT(G17, FIND("(" , G17) - 1)))) -> CLU = Commander Legends: Battle for Baldur's Gate
A18: 1 Hearthborn Battler (BLB) 139 | B18: =if(A18="","", LEFT(A18, FIND(" ", A18)-1)) -> 1 | C18: =if(A18="","",TRIM(MID(A18, FIND(" ", A18)+1, FIND("(", A18)-FIND(" ", A18)-2))) -> Hearthborn Battler | D18: =if(A18="","",VLOOKUP(E18, J:K, 2, FALSE)) -> Battlebond | E18: =if(A18="","",SUBSTITUTE(SUBSTITUTE(MID(A18, FIND("(", A18), FIND(")", A18) - FIND("(", A18) + 1), "(" , ""), ")" , "")) -> BLB | G18: CMA = Commander Anthology | J18: =if(M18="","", LEFT(M18, FIND(" = ", M18)-1)) -> CMA | K18: =if(M18="","", TRIM(MID(M18, FIND("= ", M18) + 2, LEN(M18)))) -> Commander Anthology | M18: =if(G18="","",IF(ISNUMBER(SEARCH("=", G18)), G18, TRIM(MID(G18, FIND("(" , G18) + 1, FIND(")", G18) - FIND("(" , G18) - 1)) & " = " & TRIM(LEFT(G18, FIND("(" , G18) - 1)))) -> CMA = Commander Anthology
A19: 2 Kitsa, Otterball Elite (BLB) 54 | B19: =if(A19="","", LEFT(A19, FIND(" ", A19)-1)) -> 2 | C19: =if(A19="","",TRIM(MID(A19, FIND(" ", A19)+1, FIND("(", A19)-FIND(" ", A19)-2))) -> Kitsa, Otterball Elite | D19: =if(A19="","",VLOOKUP(E19, $J:$K, 2, FALSE)) -> Battlebond | E19: =if(A19="","",SUBSTITUTE(SUBSTITUTE(MID(A19, FIND("(", A19), FIND(")", A19) - FIND("(", A19) + 1), "(" , ""), ")" , "")) -> BLB | G19: CMR = Commander Legends | J19: =if(M19="","", LEFT(M19, FIND(" = ", M19)-1)) -> CMR | K19: =if(M19="","", TRIM(MID(M19, FIND("= ", M19) + 2, LEN(M19)))) -> Commander Legends | M19: =if(G19="","",IF(ISNUMBER(SEARCH("=", G19)), G19, TRIM(MID(G19, FIND("(" , G19) + 1, FIND(")", G19) - FIND("(" , G19) - 1)) & " = " & TRIM(LEFT(G19, FIND("(" , G19) - 1)))) -> CMR = Commander Legends
A20: 1 Long River's Pull (BLB) 58 | B20: =if(A20="","", LEFT(A20, FIND(" ", A20)-1)) -> 1 | C20: =if(A20="","",TRIM(MID(A20, FIND(" ", A20)+1, FIND("(", A20)-FIND(" ", A20)-2))) -> Long River's Pull | D20: =if(A20="","",VLOOKUP(E20, $J:$K, 2, FALSE)) -> Battlebond | E20: =if(A20="","",SUBSTITUTE(SUBSTITUTE(MID(A20, FIND("(", A20), FIND(")", A20) - FIND("(", A20) + 1), "(" , ""), ")" , "")) -> BLB | G20: DAG = Duel Decks: Anthology | J20: =if(M20="","", LEFT(M20, FIND(" = ", M20)-1)) -> DAG | K20: =if(M20="","", TRIM(MID(M20, FIND("= ", M20) + 2, LEN(M20)))) -> Duel Decks: Anthology | M20: =if(G20="","",IF(ISNUMBER(SEARCH("=", G20)), G20, TRIM(MID(G20, FIND("(" , G20) + 1, FIND(")", G20) - FIND("(" , G20) - 1)) & " = " & TRIM(LEFT(G20, FIND("(" , G20) - 1)))) -> DAG = Duel Decks: Anthology
A21: 1 Patchwork Banner (BLB) 247 | B21: =if(A21="","", LEFT(A21, FIND(" ", A21)-1)) -> 1 | C21: =if(A21="","",TRIM(MID(A21, FIND(" ", A21)+1, FIND("(", A21)-FIND(" ", A21)-2))) -> Patchwork Banner | D21: =if(A21="","",VLOOKUP(E21, $J:$K, 2, FALSE)) -> Battlebond | E21: =if(A21="","",SUBSTITUTE(SUBSTITUTE(MID(A21, FIND("(", A21), FIND(")", A21) - FIND("(", A21) + 1), "(" , ""), ")" , "")) -> BLB | G21: DDD = Duel Decks: Divine vs. Demonic | J21: =if(M21="","", LEFT(M21, FIND(" = ", M21)-1)) -> DDD | K21: =if(M21="","", TRIM(MID(M21, FIND("= ", M21) + 2, LEN(M21)))) -> Duel Decks: Divine vs. Demonic | M21: =if(G21="","",IF(ISNUMBER(SEARCH("=", G21)), G21, TRIM(MID(G21, FIND("(" , G21) + 1, FIND(")", G21) - FIND("(" , G21) - 1)) & " = " & TRIM(LEFT(G21, FIND("(" , G21) - 1)))) -> DDD = Duel Decks: Divine vs. Demonic
A22: 1 Starfall Invocation (BLB) 34 | B22: =if(A22="","", LEFT(A22, FIND(" ", A22)-1)) -> 1 | C22: =if(A22="","",TRIM(MID(A22, FIND(" ", A22)+1, FIND("(", A22)-FIND(" ", A22)-2))) -> Starfall Invocation | D22: =if(A22="","",VLOOKUP(E22, $J:$K, 2, FALSE)) -> Battlebond | E22: =if(A22="","",SUBSTITUTE(SUBSTITUTE(MID(A22, FIND("(", A22), FIND(")", A22) - FIND("(", A22) + 1), "(" , ""), ")" , "")) -> BLB | G22: DDF = Duel Decks: Elves vs. Goblins | J22: =if(M22="","", LEFT(M22, FIND(" = ", M22)-1)) -> DDF | K22: =if(M22="","", TRIM(MID(M22, FIND("= ", M22) + 2, LEN(M22)))) -> Duel Decks: Elves vs. Goblins | M22: =if(G22="","",IF(ISNUMBER(SEARCH("=", G22)), G22, TRIM(MID(G22, FIND("(" , G22) + 1, FIND(")", G22) - FIND("(" , G22) - 1)) & " = " & TRIM(LEFT(G22, FIND("(" , G22) - 1)))) -> DDF = Duel Decks: Elves vs. Goblins
A23: 5 Three Tree City (BLB) 260 | B23: =if(A23="","", LEFT(A23, FIND(" ", A23)-1)) -> 5 | C23: =if(A23="","",TRIM(MID(A23, FIND(" ", A23)+1, FIND("(", A23)-FIND(" ", A23)-2))) -> Three Tree City | D23: =if(A23="","",VLOOKUP(E23, $J:$K, 2, FALSE)) -> Battlebond | E23: =if(A23="","",SUBSTITUTE(SUBSTITUTE(MID(A23, FIND("(", A23), FIND(")", A23) - FIND("(", A23) + 1), "(" , ""), ")" , "")) -> BLB | G23: DMR = Dominaria Remastered | J23: =if(M23="","", LEFT(M23, FIND(" = ", M23)-1)) -> DMR | K23: =if(M23="","", TRIM(MID(M23, FIND("= ", M23) + 2, LEN(M23)))) -> Dominaria Remastered | M23: =if(G23="","",IF(ISNUMBER(SEARCH("=", G23)), G23, TRIM(MID(G23, FIND("(" , G23) + 1, FIND(")", G23) - FIND("(" , G23) - 1)) & " = " & TRIM(LEFT(G23, FIND("(" , G23) - 1)))) -> DMR = Dominaria Remastered
A24: 1 Mass Diminish (C19) 10 | B24: =if(A24="","", LEFT(A24, FIND(" ", A24)-1)) -> 1 | C24: =if(A24="","",TRIM(MID(A24, FIND(" ", A24)+1, FIND("(", A24)-FIND(" ", A24)-2))) -> Mass Diminish | D24: =if(A24="","",VLOOKUP(E24, $J:$K, 2, FALSE)) -> Commander 2019 | E24: =if(A24="","",SUBSTITUTE(SUBSTITUTE(MID(A24, FIND("(", A24), FIND(")", A24) - FIND("(", A24) + 1), "(" , ""), ")" , "")) -> C19 | G24: DOM = Dominaria | J24: =if(M24="","", LEFT(M24, FIND(" = ", M24)-1)) -> DOM | K24: =if(M24="","", TRIM(MID(M24, FIND("= ", M24) + 2, LEN(M24)))) -> Dominaria | M24: =if(G24="","",IF(ISNUMBER(SEARCH("=", G24)), G24, TRIM(MID(G24, FIND("(" , G24) + 1, FIND(")", G24) - FIND("(" , G24) - 1)) & " = " & TRIM(LEFT(G24, FIND("(" , G24) - 1)))) -> DOM = Dominaria
A25: 2 Primal Growth (CMA) 137 | B25: =if(A25="","", LEFT(A25, FIND(" ", A25)-1)) -> 2 | C25: =if(A25="","",TRIM(MID(A25, FIND(" ", A25)+1, FIND("(", A25)-FIND(" ", A25)-2))) -> Primal Growth | D25: =if(A25="","",VLOOKUP(E25, $J:$K, 2, FALSE)) -> Commander Anthology | E25: =if(A25="","",SUBSTITUTE(SUBSTITUTE(MID(A25, FIND("(", A25), FIND(")", A25) - FIND("(", A25) + 1), "(" , ""), ")" , "")) -> CMA | G25: DPA = Duel Decks: Phyrexia vs. the Coalition | J25: =if(M25="","", LEFT(M25, FIND(" = ", M25)-1)) -> DPA | K25: =if(M25="","", TRIM(MID(M25, FIND("= ", M25) + 2, LEN(M25)))) -> Duel Decks: Phyrexia vs. the Coalition | M25: =if(G25="","",IF(ISNUMBER(SEARCH("=", G25)), G25, TRIM(MID(G25, FIND("(" , G25) + 1, FIND(")", G25) - FIND("(" , G25) - 1)) & " = " & TRIM(LEFT(G25, FIND("(" , G25) - 1)))) -> DPA = Duel Decks: Phyrexia vs. the Coalition
A26: 1 Angel of Vitality (CLU) 53 | B26: =if(A26="","", LEFT(A26, FIND(" ", A26)-1)) -> 1 | C26: =if(A26="","",TRIM(MID(A26, FIND(" ", A26)+1, FIND("(", A26)-FIND(" ", A26)-2))) -> Angel of Vitality | D26: =if(A26="","",VLOOKUP(E26, $J:$K, 2, FALSE)) -> Commander Legends: Battle for Baldur's Gate | E26: =if(A26="","",SUBSTITUTE(SUBSTITUTE(MID(A26, FIND("(", A26), FIND(")", A26) - FIND("(", A26) + 1), "(" , ""), ")" , "")) -> CLU | G26: DSC = Duskmourn: House of Horror Commander | J26: =if(M26="","", LEFT(M26, FIND(" = ", M26)-1)) -> DSC | K26: =if(M26="","", TRIM(MID(M26, FIND("= ", M26) + 2, LEN(M26)))) -> Duskmourn: House of Horror Commander | M26: =if(G26="","",IF(ISNUMBER(SEARCH("=", G26)), G26, TRIM(MID(G26, FIND("(" , G26) + 1, FIND(")", G26) - FIND("(" , G26) - 1)) & " = " & TRIM(LEFT(G26, FIND("(" , G26) - 1)))) -> DSC = Duskmourn: House of Horror Commander
A27: 1 Bag of Holding (CLB) 299 | B27: =if(A27="","", LEFT(A27, FIND(" ", A27)-1)) -> 1 | C27: =if(A27="","",TRIM(MID(A27, FIND(" ", A27)+1, FIND("(", A27)-FIND(" ", A27)-2))) -> Bag of Holding | D27: =if(A27="","",VLOOKUP(E27, $J:$K, 2, FALSE)) -> Commander Legends: Battle for Baldur's Gate | E27: =if(A27="","",SUBSTITUTE(SUBSTITUTE(MID(A27, FIND("(", A27), FIND(")", A27) - FIND("(", A27) + 1), "(" , ""), ")" , "")) -> CLB | G27: DSK = Dominaria United Commander | J27: =if(M27="","", LEFT(M27, FIND(" = ", M27)-1)) -> DSK | K27: =if(M27="","", TRIM(MID(M27, FIND("= ", M27) + 2, LEN(M27)))) -> Dominaria United Commander | M27: =if(G27="","",IF(ISNUMBER(SEARCH("=", G27)), G27, TRIM(MID(G27, FIND("(" , G27) + 1, FIND(")", G27) - FIND("(" , G27) - 1)) & " = " & TRIM(LEFT(G27, FIND("(" , G27) - 1)))) -> DSK = Dominaria United Commander
A28: 2 Everybody Lives! (WHO) 18 | B28: =if(A28="","", LEFT(A28, FIND(" ", A28)-1)) -> 2 | C28: =if(A28="","",TRIM(MID(A28, FIND(" ", A28)+1, FIND("(", A28)-FIND(" ", A28)-2))) -> Everybody Lives! | D28: =if(A28="","",VLOOKUP(E28, $J:$K, 2, FALSE)) -> Commander Legends: Battle for Baldur's Gate | E28: =if(A28="","",SUBSTITUTE(SUBSTITUTE(MID(A28, FIND("(", A28), FIND(")", A28) - FIND("(", A28) + 1), "(" , ""), ")" , "")) -> WHO | G28: DTK = Dragons of Tarkir | J28: =if(M28="","", LEFT(M28, FIND(" = ", M28)-1)) -> DTK | K28: =if(M28="","", TRIM(MID(M28, FIND("= ", M28) + 2, LEN(M28)))) -> Dragons of Tarkir | M28: =if(G28="","",IF(ISNUMBER(SEARCH("=", G28)), G28, TRIM(MID(G28, FIND("(" , G28) + 1, FIND(")", G28) - FIND("(" , G28) - 1)) & " = " & TRIM(LEFT(G28, FIND("(" , G28) - 1)))) -> DTK = Dragons of Tarkir
A29: 1 Flatline (WHO) 43 | B29: =if(A29="","", LEFT(A29, FIND(" ", A29)-1)) -> 1 | C29: =if(A29="","",TRIM(MID(A29, FIND(" ", A29)+1, FIND("(", A29)-FIND(" ", A29)-2))) -> Flatline | D29: =if(A29="","",VLOOKUP(E29, $J:$K, 2, FALSE)) -> Commander Legends: Battle for Baldur's Gate | E29: =if(A29="","",SUBSTITUTE(SUBSTITUTE(MID(A29, FIND("(", A29), FIND(")", A29) - FIND("(", A29) + 1), "(" , ""), ")" , "")) -> WHO | G29: DYN = Kaldheim | J29: =if(M29="","", LEFT(M29, FIND(" = ", M29)-1)) -> DYN | K29: =if(M29="","", TRIM(MID(M29, FIND("= ", M29) + 2, LEN(M29)))) -> Kaldheim | M29: =if(G29="","",IF(ISNUMBER(SEARCH("=", G29)), G29, TRIM(MID(G29, FIND("(" , G29) + 1, FIND(")", G29) - FIND("(" , G29) - 1)) & " = " & TRIM(LEFT(G29, FIND("(" , G29) - 1)))) -> DYN = Kaldheim
A30: 1 Herald of Ilharg (CLU) 34 | B30: =if(A30="","", LEFT(A30, FIND(" ", A30)-1)) -> 1 | C30: =if(A30="","",TRIM(MID(A30, FIND(" ", A30)+1, FIND("(", A30)-FIND(" ", A30)-2))) -> Herald of Ilharg | D30: =if(A30="","",VLOOKUP(E30, $J:$K, 2, FALSE)) -> Commander Legends: Battle for Baldur's Gate | E30: =if(A30="","",SUBSTITUTE(SUBSTITUTE(MID(A30, FIND("(", A30), FIND(")", A30) - FIND("(", A30) + 1), "(" , ""), ")" , "")) -> CLU | G30: ELD = Throne of Eldraine | J30: =if(M30="","", LEFT(M30, FIND(" = ", M30)-1)) -> ELD | K30: =if(M30="","", TRIM(MID(M30, FIND("= ", M30) + 2, LEN(M30)))) -> Throne of Eldraine | M30: =if(G30="","",IF(ISNUMBER(SEARCH("=", G30)), G30, TRIM(MID(G30, FIND("(" , G30) + 1, FIND(")", G30) - FIND("(" , G30) - 1)) & " = " & TRIM(LEFT(G30, FIND("(" , G30) - 1)))) -> ELD = Throne of Eldraine
... A32: 1 Quantum Misalignment (WHO) 52 | B32: =if(A32="","", LEFT(A32, FIND(" ", A32)-1)) -> 1 | C32: =if(A32="","",TRIM(MID(A32, FIND(" ", A32)+1, FIND("(", A32)-FIND(" ", A32)-2))) -> Quantum Misalignment | D32: =if(A32="","",VLOOKUP(E32, $J:$K, 2, FALSE)) -> Commander Legends: Battle for Baldur's Gate | E32: =if(A32="","",SUBSTITUTE(SUBSTITUTE(MID(A32, FIND("(", A32), FIND(")", A32) - FIND("(", A32) + 1), "(" , ""), ")" , "")) -> WHO | G32: EVE = Eventide | J32: =if(M32="","", LEFT(M32, FIND(" = ", M32)-1)) -> EVE | K32: =if(M32="","", TRIM(MID(M32, FIND("= ", M32) + 2, LEN(M32)))) -> Eventide | M32: =if(G32="","",IF(ISNUMBER(SEARCH("=", G32)), G32, TRIM(MID(G32, FIND("(" , G32) + 1, FIND(")", G32) - FIND("(" , G32) - 1)) & " = " & TRIM(LEFT(G32, FIND("(" , G32) - 1)))) -> EVE = Eventide
A33: 2 Suppressor Skyguard (CLU) 46 | B33: =if(A33="","", LEFT(A33, FIND(" ", A33)-1)) -> 2 | C33: =if(A33="","",TRIM(MID(A33, FIND(" ", A33)+1, FIND("(", A33)-FIND(" ", A33)-2))) -> Suppressor Skyguard | D33: =if(A33="","",VLOOKUP(E33, J:K, 2, FALSE)) -> Commander Legends: Battle for Baldur's Gate | E33: =if(A33="","",SUBSTITUTE(SUBSTITUTE(MID(A33, FIND("(", A33), FIND(")", A33) - FIND("(", A33) + 1), "(" , ""), ")" , "")) -> CLU | G33: FUT = Future Sight | J33: =if(M33="","", LEFT(M33, FIND(" = ", M33)-1)) -> FUT | K33: =if(M33="","", TRIM(MID(M33, FIND("= ", M33) + 2, LEN(M33)))) -> Future Sight | M33: =if(G33="","",IF(ISNUMBER(SEARCH("=", G33)), G33, TRIM(MID(G33, FIND("(" , G33) + 1, FIND(")", G33) - FIND("(" , G33) - 1)) & " = " & TRIM(LEFT(G33, FIND("(" , G33) - 1)))) -> FUT = Future Sight
A34: 1 Abundance (CMM) 884 | B34: =if(A34="","", LEFT(A34, FIND(" ", A34)-1)) -> 1 | C34: =if(A34="","",TRIM(MID(A34, FIND(" ", A34)+1, FIND("(", A34)-FIND(" ", A34)-2))) -> Abundance | D34: =if(A34="","",VLOOKUP(E34, $J:$K, 2, FALSE)) -> Commander Masters | E34: =if(A34="","",SUBSTITUTE(SUBSTITUTE(MID(A34, FIND("(", A34), FIND(")", A34) - FIND("(", A34) + 1), "(" , ""), ")" , "")) -> CMM | G34: GDS = Guilds of Ravnica: The Gathering | J34: =if(M34="","", LEFT(M34, FIND(" = ", M34)-1)) -> GDS | K34: =if(M34="","", TRIM(MID(M34, FIND("= ", M34) + 2, LEN(M34)))) -> Guilds of Ravnica: The Gathering | M34: =if(G34="","",IF(ISNUMBER(SEARCH("=", G34)), G34, TRIM(MID(G34, FIND("(" , G34) + 1, FIND(")", G34) - FIND("(" , G34) - 1)) & " = " & TRIM(LEFT(G34, FIND("(" , G34) - 1)))) -> GDS = Guilds of Ravnica: The Gathering
A35: 1 Ajani, Strength of the Pride (M20) 2 | B35: =if(A35="","", LEFT(A35, FIND(" ", A35)-1)) -> 1 | C35: =if(A35="","",TRIM(MID(A35, FIND(" ", A35)+1, FIND("(", A35)-FIND(" ", A35)-2))) -> Ajani, Strength of the Pride | D35: =if(A35="","",VLOOKUP(E35, $J:$K, 2, FALSE)) -> Core Set 2020 | E35: =if(A35="","",SUBSTITUTE(SUBSTITUTE(MID(A35, FIND("(", A35), FIND(")", A35) - FIND("(", A35) + 1), "(" , ""), ")" , "")) -> M20 | G35: GRN = Guilds of Ravnica | J35: =if(M35="","", LEFT(M35, FIND(" = ", M35)-1)) -> GRN | K35: =if(M35="","", TRIM(MID(M35, FIND("= ", M35) + 2, LEN(M35)))) -> Guilds of Ravnica | M35: =if(G35="","",IF(ISNUMBER(SEARCH("=", G35)), G35, TRIM(MID(G35, FIND("(" , G35) + 1, FIND(")", G35) - FIND("(" , G35) - 1)) & " = " & TRIM(LEFT(G35, FIND("(" , G35) - 1)))) -> GRN = Guilds of Ravnica
A36: 1 Exploration (DMR) 159 | B36: =if(A36="","", LEFT(A36, FIND(" ", A36)-1)) -> 1 | C36: =if(A36="","",TRIM(MID(A36, FIND(" ", A36)+1, FIND("(", A36)-FIND(" ", A36)-2))) -> Exploration | D36: =if(A36="","",VLOOKUP(E36, $J:$K, 2, FALSE)) -> Dominaria Remastered | E36: =if(A36="","",SUBSTITUTE(SUBSTITUTE(MID(A36, FIND("(", A36), FIND(")", A36) - FIND("(", A36) + 1), "(" , ""), ")" , "")) -> DMR | G36: HOU = Hour of Devastation | J36: =if(M36="","", LEFT(M36, FIND(" = ", M36)-1)) -> HOU | K36: =if(M36="","", TRIM(MID(M36, FIND("= ", M36) + 2, LEN(M36)))) -> Hour of Devastation | M36: =if(G36="","",IF(ISNUMBER(SEARCH("=", G36)), G36, TRIM(MID(G36, FIND("(" , G36) + 1, FIND(")", G36) - FIND("(" , G36) - 1)) & " = " & TRIM(LEFT(G36, FIND("(" , G36) - 1)))) -> HOU = Hour of Devastation
A37: 1 Krosan Restorer (DMR) 168 | B37: =if(A37="","", LEFT(A37, FIND(" ", A37)-1)) -> 1 | C37: =if(A37="","",TRIM(MID(A37, FIND(" ", A37)+1, FIND("(", A37)-FIND(" ", A37)-2))) -> Krosan Restorer | D37: =if(A37="","",VLOOKUP(E37, $J:$K, 2, FALSE)) -> Dominaria Remastered | E37: =if(A37="","",SUBSTITUTE(SUBSTITUTE(MID(A37, FIND("(", A37), FIND(")", A37) - FIND("(", A37) + 1), "(" , ""), ")" , "")) -> DMR | G37: IKO = Ikoria: Lair of Behemoths | J37: =if(M37="","", LEFT(M37, FIND(" = ", M37)-1)) -> IKO | K37: =if(M37="","", TRIM(MID(M37, FIND("= ", M37) + 2, LEN(M37)))) -> Ikoria: Lair of Behemoths | M37: =if(G37="","",IF(ISNUMBER(SEARCH("=", G37)), G37, TRIM(MID(G37, FIND("(" , G37) + 1, FIND(")", G37) - FIND("(" , G37) - 1)) & " = " & TRIM(LEFT(G37, FIND("(" , G37) - 1)))) -> IKO = Ikoria: Lair of Behemoths
A38: 1 Overmaster (DMR) 132 | B38: =if(A38="","", LEFT(A38, FIND(" ", A38)-1)) -> 1 | C38: =if(A38="","",TRIM(MID(A38, FIND(" ", A38)+1, FIND("(", A38)-FIND(" ", A38)-2))) -> Overmaster | D38: =if(A38="","",VLOOKUP(E38, $J:$K, 2, FALSE)) -> Dominaria Remastered | E38: =if(A38="","",SUBSTITUTE(SUBSTITUTE(MID(A38, FIND("(", A38), FIND(")", A38) - FIND("(", A38) + 1), "(" , ""), ")" , "")) -> DMR | G38: KLD = Kaladesh | J38: =if(M38="","", LEFT(M38, FIND(" = ", M38)-1)) -> KLD | K38: =if(M38="","", TRIM(MID(M38, FIND("= ", M38) + 2, LEN(M38)))) -> Kaladesh | M38: =if(G38="","",IF(ISNUMBER(SEARCH("=", G38)), G38, TRIM(MID(G38, FIND("(" , G38) + 1, FIND(")", G38) - FIND("(" , G38) - 1)) & " = " & TRIM(LEFT(G38, FIND("(" , G38) - 1)))) -> KLD = Kaladesh
A39: 1 Blazemire Verge (DSK) 256 | B39: =if(A39="","", LEFT(A39, FIND(" ", A39)-1)) -> 1 | C39: =if(A39="","",TRIM(MID(A39, FIND(" ", A39)+1, FIND("(", A39)-FIND(" ", A39)-2))) -> Blazemire Verge | D39: =if(A39="","",VLOOKUP(E39, $J:$K, 2, FALSE)) -> Dominaria United Commander | E39: =if(A39="","",SUBSTITUTE(SUBSTITUTE(MID(A39, FIND("(", A39), FIND(")", A39) - FIND("(", A39) + 1), "(" , ""), ")" , "")) -> DSK | G39: KTK = Khans of Tarkir | J39: =if(M39="","", LEFT(M39, FIND(" = ", M39)-1)) -> KTK | K39: =if(M39="","", TRIM(MID(M39, FIND("= ", M39) + 2, LEN(M39)))) -> Khans of Tarkir | M39: =if(G39="","",IF(ISNUMBER(SEARCH("=", G39)), G39, TRIM(MID(G39, FIND("(" , G39) + 1, FIND(")", G39) - FIND("(" , G39) - 1)) & " = " & TRIM(LEFT(G39, FIND("(" , G39) - 1)))) -> KTK = Khans of Tarkir
A40: 1 Dollmaker's Shop // Porcelain Gallery (DSK) 4 | B40: =if(A40="","", LEFT(A40, FIND(" ", A40)-1)) -> 1 | C40: =if(A40="","",TRIM(MID(A40, FIND(" ", A40)+1, FIND("(", A40)-FIND(" ", A40)-2))) -> Dollmaker's Shop // Porcelain Gallery | D40: =if(A40="","",VLOOKUP(E40, $J:$K, 2, FALSE)) -> Dominaria United Commander | E40: =if(A40="","",SUBSTITUTE(SUBSTITUTE(MID(A40, FIND("(", A40), FIND(")", A40) - FIND("(", A40) + 1), "(" , ""), ")" , "")) -> DSK | G40: LCC = The Lost Caverns of Ixalan Commander | J40: =if(M40="","", LEFT(M40, FIND(" = ", M40)-1)) -> LCC | K40: =if(M40="","", TRIM(MID(M40, FIND("= ", M40) + 2, LEN(M40)))) -> The Lost Caverns of Ixalan Commander | M40: =if(G40="","",IF(ISNUMBER(SEARCH("=", G40)), G40, TRIM(MID(G40, FIND("(" , G40) + 1, FIND(")", G40) - FIND("(" , G40) - 1)) & " = " & TRIM(LEFT(G40, FIND("(" , G40) - 1)))) -> LCC = The Lost Caverns of Ixalan Commander
